<?xml version='1.0' encoding='utf-8'?>
<robot name="robot">
    <link name="base_arm">
        <inertial>
            <origin xyz="-0.00584646080312836 -7.3873373338071754e-09 -0.004012834319885124" rpy="0.0 0.0 0.0" />
            <mass value="0.13361686399416903" />
            <inertia ixx="5.8939729020783356e-05" iyy="5.6592918012148005e-05" izz="6.854371519910996e-05" ixy="-6.99349705446744e-11" iyz="-8.5886773028627e-12" ixz="-1.7907551978337e-07" />
        </inertial>
        <visual name="base_arm_visual">
            <origin xyz="0.0 0.0 0.0" rpy="0.0 0.0 0.0" />
            <geometry>
                <mesh filename="package://microspot_description/meshes/base_arm.stl" scale="0.001 0.001 0.001" />
            </geometry>
        </visual>
        <collision name="base_arm_collision">
            <origin xyz="0.0 0.0 0.0" rpy="0.0 0.0 0.0" />
            <geometry>
                <mesh filename="package://microspot_description/meshes/base_arm.stl" scale="0.001 0.001 0.001" />
            </geometry>
        </collision>
    </link>
    <link name="rotor_1">
        <inertial>
            <origin xyz="-3.390200786768105e-11 -0.005121532313427566 -4.748528394937779e-09" rpy="0.0 -0.0 -8.572071991599574e-76" />
            <mass value="0.0205825708955109" />
            <inertia ixx="3.276012308613693e-06" iyy="2.3136165056857327e-06" izz="3.276012308163427e-06" ixy="7.167619481203728e-15" iyz="-1.2825779663588194e-14" ixz="-7.279566320128172e-15" />
        </inertial>
        <visual name="rotor_1_visual">
            <origin xyz="-9.992007221626409e-17 -0.003800001056510016 -4.809081373124969e-09" rpy="1.5707963267948974 -4.733165431326075e-30 1.2767446198576543e-15" />
            <geometry>
                <mesh filename="package://microspot_description/meshes/rotor_1.stl" scale="0.001 0.001 0.001" />
            </geometry>
        </visual>
        <collision name="rotor_1_collision">
            <origin xyz="-9.992007221626409e-17 -0.003800001056510016 -4.809081373124969e-09" rpy="1.5707963267948974 -4.733165431326075e-30 1.2767446198576543e-15" />
            <geometry>
                <mesh filename="package://microspot_description/meshes/rotor_1.stl" scale="0.001 0.001 0.001" />
            </geometry>
        </collision>
    </link>
    <link name="link_1">
        <inertial>
            <origin xyz="5.800542224543293e-08 0.025455863746017764 0.005860275071672178" rpy="0.0 -0.0 0.0" />
            <mass value="0.03936689997861309" />
            <inertia ixx="1.3812710808048091e-05" iyy="9.199611516837318e-06" izz="1.6104361536498297e-05" ixy="7.211364804390603e-12" iyz="-2.7826085290265784e-07" ixz="-4.050635108552315e-11" />
        </inertial>
        <visual name="link_1_visual">
            <origin xyz="-8.992806499463768e-16 0.03199999894348995 0.004999995190918689" rpy="-9.159339953157616e-16 -1.224646799147093e-16 -3.1415926535897687" />
            <geometry>
                <mesh filename="package://microspot_description/meshes/link_1.stl" scale="0.001 0.001 0.001" />
            </geometry>
        </visual>
        <collision name="link_1_collision">
            <origin xyz="-8.992806499463768e-16 0.03199999894348995 0.004999995190918689" rpy="-9.159339953157616e-16 -1.224646799147093e-16 -3.1415926535897687" />
            <geometry>
                <mesh filename="package://microspot_description/meshes/link_1.stl" scale="0.001 0.001 0.001" />
            </geometry>
        </collision>
    </link>
    <link name="link_2">
        <inertial>
            <origin xyz="0.007097385776134644 6.23124624787863e-09 0.01670261555933651" rpy="0.0 -0.0 -5.309020986220915e-93" />
            <mass value="0.022783062974825415" />
            <inertia ixx="6.3237490239767406e-06" iyy="5.892532951500359e-06" izz="6.323750024922161e-06" ixy="-8.165228861392539e-13" iyz="1.482501594358629e-12" ixz="-1.431870726659993e-06" />
        </inertial>
        <visual name="link_2_visual">
            <origin xyz="0.02379999999999961 -1.0565094843428823e-09 0.02379999846388836" rpy="-2.4589004585091578e-14 1.5707963267948832 0" />
            <geometry>
                <mesh filename="package://microspot_description/meshes/link_2.stl" scale="0.001 0.001 0.001" />
            </geometry>
        </visual>
        <collision name="link_2_collision">
            <origin xyz="0.02379999999999961 -1.0565094843428823e-09 0.02379999846388836" rpy="-2.4589004585091578e-14 1.5707963267948832 0" />
            <geometry>
                <mesh filename="package://microspot_description/meshes/link_2.stl" scale="0.001 0.001 0.001" />
            </geometry>
        </collision>
    </link>
    <link name="link_3">
        <inertial>
            <origin xyz="0.04072797462224379 -0.0002336673898725916 -9.688549336344998e-05" rpy="0.0 -0.0 0.0" />
            <mass value="0.04251854931472677" />
            <inertia ixx="7.593853554059267e-06" iyy="3.2397711764130295e-05" izz="3.2304781476408075e-05" ixy="-3.687487938934747e-07" iyz="4.646748698439151e-08" ixz="-1.5273906064995383e-07" />
        </inertial>
        <visual name="link_3_visual">
            <origin xyz="0.03999999999999957 -1.0565094399339615e-09 -1.5361121974422077e-09" rpy="-1.942890293093907e-15 1.570796326794884 0" />
            <geometry>
                <mesh filename="package://microspot_description/meshes/link_3.stl" scale="0.001 0.001 0.001" />
            </geometry>
        </visual>
        <collision name="link_3_collision">
            <origin xyz="0.03999999999999957 -1.0565094399339615e-09 -1.5361121974422077e-09" rpy="-1.942890293093907e-15 1.570796326794884 0" />
            <geometry>
                <mesh filename="package://microspot_description/meshes/link_3.stl" scale="0.001 0.001 0.001" />
            </geometry>
        </collision>
    </link>
    <link name="link_6">
        <inertial>
            <origin xyz="-7.287757348706237e-09 0.007097381848042561 -0.016702619032948795" rpy="-1.0947644252537633e-47 -3.373503341833768e-80 3.421138828918011e-49" />
            <mass value="0.022783062974825415" />
            <inertia ixx="5.892532951500357e-06" iyy="6.323750024922186e-06" izz="6.323749023976876e-06" ixy="1.4825015130434656e-12" iyz="1.4318707266599923e-06" ixz="8.165229018093633e-13" />
        </inertial>
        <visual name="link_6_visual">
            <origin xyz="-9.947598300641404e-16 -1.0565095287518034e-09 -4.809083933299263e-09" rpy="1.3845811097559858e-14 -6.557254739181815e-16 1.5707963267948966" />
            <geometry>
                <mesh filename="package://microspot_description/meshes/link_6.stl" scale="0.001 0.001 0.001" />
            </geometry>
        </visual>
        <collision name="link_6_collision">
            <origin xyz="-9.947598300641404e-16 -1.0565095287518034e-09 -4.809083933299263e-09" rpy="1.3845811097559858e-14 -6.557254739181815e-16 1.5707963267948966" />
            <geometry>
                <mesh filename="package://microspot_description/meshes/link_6.stl" scale="0.001 0.001 0.001" />
            </geometry>
        </collision>
    </link>
    <link name="link_7">
        <inertial>
            <origin xyz="0.00023366152427933495 0.040727973565734724 -9.688395724996468e-05" rpy="-3.421138828918011e-49 -0.0 0.0" />
            <mass value="0.04251854931472677" />
            <inertia ixx="3.239771176412982e-05" iyy="7.593853554059428e-06" izz="3.2304781476407695e-05" ixy="3.687487938933595e-07" iyz="-1.5273906065036038e-07" ixz="-4.646748698441862e-08" />
        </inertial>
        <visual name="link_7_visual">
            <origin xyz="-4.809083814505399e-09 0.03999999894349049 1.2789769243681803e-15" rpy="-1.570796326794896 1.5707963267948828 0" />
            <geometry>
                <mesh filename="package://microspot_description/meshes/link_7.stl" scale="0.001 0.001 0.001" />
            </geometry>
        </visual>
        <collision name="link_7_collision">
            <origin xyz="-4.809083814505399e-09 0.03999999894349049 1.2789769243681803e-15" rpy="-1.570796326794896 1.5707963267948828 0" />
            <geometry>
                <mesh filename="package://microspot_description/meshes/link_7.stl" scale="0.001 0.001 0.001" />
            </geometry>
        </collision>
    </link>
    <link name="link_9">
        <inertial>
            <origin xyz="3.996039300346865e-08 -0.0132755710306947 -0.006746442857581461" rpy="0.0 -0.0 0.0" />
            <mass value="0.0209803714773982" />
            <inertia ixx="4.550340283417196e-06" iyy="4.1310510718392405e-06" izz="4.51630547159982e-06" ixy="6.693205668525937e-12" iyz="-6.826126048874953e-07" ixz="1.1018164191353014e-12" />
        </inertial>
        <visual name="link_9_visual">
            <origin xyz="-1.7763568394002506e-16 -0.011799998943490415 0.007000004809083742" rpy="-1.370946862983727e-14 -6.557254739191129e-16 1.5707963267949794" />
            <geometry>
                <mesh filename="package://microspot_description/meshes/link_9.stl" scale="0.001 0.001 0.001" />
            </geometry>
        </visual>
        <collision name="link_9_collision">
            <origin xyz="-1.7763568394002506e-16 -0.011799998943490415 0.007000004809083742" rpy="-1.370946862983727e-14 -6.557254739191129e-16 1.5707963267949794" />
            <geometry>
                <mesh filename="package://microspot_description/meshes/link_9.stl" scale="0.001 0.001 0.001" />
            </geometry>
        </collision>
    </link>
    <link name="rotor_6">
        <inertial>
            <origin xyz="-0.00010306216161254156 -4.269114606803015e-05 -0.0010844920284093984" rpy="0.0 -0.0 0.0" />
            <mass value="0.01612604189282462" />
            <inertia ixx="1.822800972856465e-06" iyy="1.8034379757027796e-06" izz="2.0300889289122815e-06" ixy="9.682180126006565e-09" iyz="7.670681233384468e-09" ixz="1.8517915402200668e-08" />
        </inertial>
        <visual name="rotor_6_visual">
            <origin xyz="-3.730349362740526e-16 1.0565077701585324e-09 -0.0038000019179390775" rpy="-3.1415926535897927 2.344905375549829e-13 -5.1131491472677587e-14" />
            <geometry>
                <mesh filename="package://microspot_description/meshes/rotor_6.stl" scale="0.001 0.001 0.001" />
            </geometry>
        </visual>
        <collision name="rotor_6_collision">
            <origin xyz="-3.730349362740526e-16 1.0565077701585324e-09 -0.0038000019179390775" rpy="-3.1415926535897927 2.344905375549829e-13 -5.1131491472677587e-14" />
            <geometry>
                <mesh filename="package://microspot_description/meshes/rotor_6.stl" scale="0.001 0.001 0.001" />
            </geometry>
        </collision>
    </link>
    <link name="rotor_2">
        <inertial>
            <origin xyz="0.00010306216161213743 4.2691146065756416e-05 -0.0010844916465815825" rpy="0.0 -0.0 0.0" />
            <mass value="0.01612604189282462" />
            <inertia ixx="1.8228009728566953e-06" iyy="1.8034379757027635e-06" izz="2.0300889289126068e-06" ixy="9.682180126174277e-09" iyz="-7.670681233404796e-09" ixz="-1.8517915402149e-08" />
        </inertial>
        <visual name="rotor_2_visual">
            <origin xyz="-6.683542608243443e-16 -1.0565100350135026e-09 -0.0038000015361112373" rpy="3.1415926535897922 -6.245004513516283e-16 -3.1415926535897687" />
            <geometry>
                <mesh filename="package://microspot_description/meshes/rotor_2.stl" scale="0.001 0.001 0.001" />
            </geometry>
        </visual>
        <collision name="rotor_2_collision">
            <origin xyz="-6.683542608243443e-16 -1.0565100350135026e-09 -0.0038000015361112373" rpy="3.1415926535897922 -6.245004513516283e-16 -3.1415926535897687" />
            <geometry>
                <mesh filename="package://microspot_description/meshes/rotor_2.stl" scale="0.001 0.001 0.001" />
            </geometry>
        </collision>
    </link>
    <link name="rotor_3">
        <inertial>
            <origin xyz="-0.00010306216161371396 4.269114606626268e-05 0.0010844853013863398" rpy="0.0 -0.0 -3.4211388289180104e-49" />
            <mass value="0.01612604189282462" />
            <inertia ixx="1.8228009728567224e-06" iyy="1.8034379757026708e-06" izz="2.030088928912606e-06" ixy="-9.682180126169194e-09" iyz="7.670681233404793e-09" ixz="-1.8517915402146455e-08" />
        </inertial>
        <visual name="rotor_3_visual">
            <origin xyz="-8.881784197001252e-16 -1.0565095287518034e-09 0.003799995190915997" rpy="6.834810495338117e-16 1.4151122429331707e-14 5.329394922397053e-17" />
            <geometry>
                <mesh filename="package://microspot_description/meshes/rotor_3.stl" scale="0.001 0.001 0.001" />
            </geometry>
        </visual>
        <collision name="rotor_3_collision">
            <origin xyz="-8.881784197001252e-16 -1.0565095287518034e-09 0.003799995190915997" rpy="6.834810495338117e-16 1.4151122429331707e-14 5.329394922397053e-17" />
            <geometry>
                <mesh filename="package://microspot_description/meshes/rotor_3.stl" scale="0.001 0.001 0.001" />
            </geometry>
        </collision>
    </link>
    <link name="rotor_4">
        <inertial>
            <origin xyz="0.00010306216161342973 -4.269114606593405e-05 0.00108449491955406" rpy="0.0 -0.0 0.0" />
            <mass value="0.01612604189282462" />
            <inertia ixx="1.822800972856465e-06" iyy="1.8034379757027796e-06" izz="2.030088928912715e-06" ixy="-9.682180126006565e-09" iyz="-7.670681233384468e-09" ixz="1.8517915402173563e-08" />
        </inertial>
        <visual name="rotor_4_visual">
            <origin xyz="9.592326932761353e-16 1.0565098307324661e-09 0.0038000048090837167" rpy="-7.251144129569485e-16 -1.3047380017614925e-13 -3.141592653589711" />
            <geometry>
                <mesh filename="package://microspot_description/meshes/rotor_4.stl" scale="0.001 0.001 0.001" />
            </geometry>
        </visual>
        <collision name="rotor_4_collision">
            <origin xyz="9.592326932761353e-16 1.0565098307324661e-09 0.0038000048090837167" rpy="-7.251144129569485e-16 -1.3047380017614925e-13 -3.141592653589711" />
            <geometry>
                <mesh filename="package://microspot_description/meshes/rotor_4.stl" scale="0.001 0.001 0.001" />
            </geometry>
        </collision>
    </link>
    <link name="link_10">
        <inertial>
            <origin xyz="-0.006746447666667415 -4.101690226576693e-08 0.013275567278119613" rpy="0.0 -0.0 -2.023054920004153e-88" />
            <mass value="0.0209803714773982" />
            <inertia ixx="4.516305471598736e-06" iyy="4.550340283416545e-06" izz="4.131051071839566e-06" ixy="-1.1018163378201384e-12" iyz="6.693205289055176e-12" ixz="6.82612604887558e-07" />
        </inertial>
        <visual name="link_10_visual">
            <origin xyz="0.006999999999997968 -1.0565105057480651e-09 0.01179999519091699" rpy="8.201665736784098e-14 1.5707963267947749 0" />
            <geometry>
                <mesh filename="package://microspot_description/meshes/link_10.stl" scale="0.001 0.001 0.001" />
            </geometry>
        </visual>
        <collision name="link_10_collision">
            <origin xyz="0.006999999999997968 -1.0565105057480651e-09 0.01179999519091699" rpy="8.201665736784098e-14 1.5707963267947749 0" />
            <geometry>
                <mesh filename="package://microspot_description/meshes/link_10.stl" scale="0.001 0.001 0.001" />
            </geometry>
        </collision>
    </link>
    <link name="rotor_5">
        <inertial>
            <origin xyz="0.0010844901166393583 -4.269114606806568e-05 -0.00010305735252577719" rpy="0.0 -0.0 0.0" />
            <mass value="0.016126041892824617" />
            <inertia ixx="2.030088928912715e-06" iyy="1.8034379777363092e-06" izz="1.8228009748904282e-06" ixy="-7.670681237653514e-09" iyz="9.682180126223405e-09" ixz="-1.851791541244638e-08" />
        </inertial>
        <visual name="rotor_5_visual">
            <origin xyz="0.01879999999999736 1.0565089780811832e-09 4.809084828139021e-09" rpy="-3.141592653589726 -1.5707963267947747 0" />
            <geometry>
                <mesh filename="package://microspot_description/meshes/rotor_5.stl" scale="0.001 0.001 0.001" />
            </geometry>
        </visual>
        <collision name="rotor_5_collision">
            <origin xyz="0.01879999999999736 1.0565089780811832e-09 4.809084828139021e-09" rpy="-3.141592653589726 -1.5707963267947747 0" />
            <geometry>
                <mesh filename="package://microspot_description/meshes/rotor_5.stl" scale="0.001 0.001 0.001" />
            </geometry>
        </collision>
    </link>
    <link name="link_4">
        <inertial>
            <origin xyz="0.03927202537775532 -0.00023366738987252056 9.688242113801592e-05" rpy="0.0 -0.0 0.0" />
            <mass value="0.04251854931472677" />
            <inertia ixx="7.593853554059267e-06" iyy="3.239771176412971e-05" izz="3.230478147640782e-05" ixy="3.6874879389347474e-07" iyz="-4.646748698439152e-08" ixz="-1.5273906064987254e-07" />
        </inertial>
        <visual name="link_4_visual">
            <origin xyz="0.039999999999999536 -1.0565093688796879e-09 -1.5361132366109587e-09" rpy="-4.440892098500629e-16 -1.5707963267948832 0" />
            <geometry>
                <mesh filename="package://microspot_description/meshes/link_4.stl" scale="0.001 0.001 0.001" />
            </geometry>
        </visual>
        <collision name="link_4_collision">
            <origin xyz="0.039999999999999536 -1.0565093688796879e-09 -1.5361132366109587e-09" rpy="-4.440892098500629e-16 -1.5707963267948832 0" />
            <geometry>
                <mesh filename="package://microspot_description/meshes/link_4.stl" scale="0.001 0.001 0.001" />
            </geometry>
        </collision>
    </link>
    <link name="link_8">
        <inertial>
            <origin xyz="9.688395725003574e-05 0.0392720243212462 -0.00023367114244691623" rpy="0.0 -0.0 0.0" />
            <mass value="0.04251854931472677" />
            <inertia ixx="3.230478147640825e-05" iyy="7.59385355405943e-06" izz="3.239771176413069e-05" ixy="-1.5273906065036043e-07" iyz="3.687487938933731e-07" ixz="-4.6467486984418625e-08" />
        </inertial>
        <visual name="link_8_visual">
            <origin xyz="-1.2079226507921704e-15 0.03999999894349042 -4.809083762324917e-09" rpy="1.5707963267948972 1.3770700969794588e-14 -2.133675335684832e-15" />
            <geometry>
                <mesh filename="package://microspot_description/meshes/link_8.stl" scale="0.001 0.001 0.001" />
            </geometry>
        </visual>
        <collision name="link_8_collision">
            <origin xyz="-1.2079226507921704e-15 0.03999999894349042 -4.809083762324917e-09" rpy="1.5707963267948972 1.3770700969794588e-14 -2.133675335684832e-15" />
            <geometry>
                <mesh filename="package://microspot_description/meshes/link_8.stl" scale="0.001 0.001 0.001" />
            </geometry>
        </collision>
    </link>
    <link name="link_5">
        <inertial>
            <origin xyz="0.025455864802527265 -5.69489136026391e-08 0.005860281416867572" rpy="0.0 -0.0 0.0" />
            <mass value="0.03936689997861309" />
            <inertia ixx="9.199611516837267e-06" iyy="1.3812710808047603e-05" izz="1.610436153649808e-05" ixy="-7.211364643454343e-12" iyz="4.05063510402863e-11" ixz="-2.7826085290274085e-07" />
        </inertial>
        <visual name="link_5_visual">
            <origin xyz="0.031999999999999425 1.0565093866432563e-09 0.005000001536114169" rpy="-1.3350478574602292e-14 -8.690964614643824e-16 1.5707963267948968" />
            <geometry>
                <mesh filename="package://microspot_description/meshes/link_5.stl" scale="0.001 0.001 0.001" />
            </geometry>
        </visual>
        <collision name="link_5_collision">
            <origin xyz="0.031999999999999425 1.0565093866432563e-09 0.005000001536114169" rpy="-1.3350478574602292e-14 -8.690964614643824e-16 1.5707963267948968" />
            <geometry>
                <mesh filename="package://microspot_description/meshes/link_5.stl" scale="0.001 0.001 0.001" />
            </geometry>
        </collision>
    </link>
    <link name="link_11">
        <inertial>
            <origin xyz="-0.02545586480252986 -5.90619312035301e-08 -0.005860284689844848" rpy="0.0 -0.0 0.0" />
            <mass value="0.03936689997861309" />
            <inertia ixx="9.199611516836834e-06" iyy="1.3812710808047925e-05" izz="1.6104361536496338e-05" ixy="7.211364318193691e-12" iyz="-4.0506350986076177e-11" ixz="-2.782608529034455e-07" />
        </inertial>
        <visual name="link_11_visual">
            <origin xyz="-0.032000000000002124 -1.0565085517555418e-09 -0.005000004809092156" rpy="3.141592653589671 -2.3141489217343506e-16 1.5707963267949472" />
            <geometry>
                <mesh filename="package://microspot_description/meshes/link_11.stl" scale="0.001 0.001 0.001" />
            </geometry>
        </visual>
        <collision name="link_11_collision">
            <origin xyz="-0.032000000000002124 -1.0565085517555418e-09 -0.005000004809092156" rpy="3.141592653589671 -2.3141489217343506e-16 1.5707963267949472" />
            <geometry>
                <mesh filename="package://microspot_description/meshes/link_11.stl" scale="0.001 0.001 0.001" />
            </geometry>
        </collision>
    </link>
    <link name="gripper">
        <inertial>
            <origin xyz="-0.006365222405004882 -6.125265525689372e-05 -0.00984640355966235" rpy="0.0 -0.0 0.0" />
            <mass value="0.01596854737626013" />
            <inertia ixx="3.1651654420490182e-06" iyy="2.8012730216299647e-06" izz="4.535426013899026e-06" ixy="2.3297846950265377e-09" iyz="-6.202322222438258e-10" ixz="2.515477987843466e-07" />
        </inertial>
        <visual name="gripper_visual">
            <origin xyz="-0.04776299865158101 -0.08187592825209163 -0.10384365589986533" rpy="5.1009026792762795e-14 -1.5707963267948943 0" />
            <geometry>
                <mesh filename="package://microspot_description/meshes/gripper.stl" scale="0.001 0.001 0.001" />
            </geometry>
        </visual>
        <collision name="gripper_collision">
            <origin xyz="-0.04776299865158101 -0.08187592825209163 -0.10384365589986533" rpy="5.1009026792762795e-14 -1.5707963267948943 0" />
            <geometry>
                <mesh filename="package://microspot_description/meshes/gripper.stl" scale="0.001 0.001 0.001" />
            </geometry>
        </collision>
    </link>
    <joint name="rotor_1_Rigid-16" type="fixed">
        <origin xyz="0.0 0.0092 0.0" rpy="1.9721522630525295e-31 -1.9721522630525295e-31 -1.401298464324817e-45" />
        <parent link="rotor_1" />
        <child link="link_1" />
    </joint>
    <joint name="joint_2" type="revolute">
        <origin xyz="0.0 0.021800000000000007 0.026146680000000002" rpy="3.14 1.9721522630524862e-31 3.048372673850124e-30" />
        <parent link="link_1" />
        <child link="rotor_2" />
        <axis xyz="0.0 -1.9721522630525295e-31 -1.0" />
        <limit lower="0.628" upper="3.7" effort="1000000" velocity="1000000" />
    </joint>
    <joint name="rotor_2_Rigid-19" type="fixed">
        <origin xyz="0.0 0.0 0.0092" rpy="1.9721522630525295e-31 -9.860761315262648e-32 -2.5023715346163465e-30" />
        <parent link="rotor_2" />
        <child link="link_2" />
    </joint>
    <joint name="link_2_Rigid-20" type="fixed">
        <origin xyz="0.023799999999999998 0.0 0.023799999999999998" rpy="7.236103987053064e-30 -1.4791141972893971e-30 -5.460011392337774e-31" />
        <parent link="link_2" />
        <child link="link_3" />
    </joint>
    <joint name="joint_1" type="revolute">
        <origin xyz="-0.005299999999999895 4.809081373124969e-09 -0.04150000105651003" rpy="-1.5707963267948974 -2.1926904736346838e-15 -3.686229913557171e-30" />
        <parent link="base_arm" />
        <child link="rotor_1" />
        <axis xyz="-1.401298464324817e-45 -1.0 1.9721522630525295e-31" />
        <limit lower="0.0" upper="3.141593" effort="1000000" velocity="1000000" />
    </joint>
    <joint name="rotor_3_Rigid-26" type="fixed">
        <origin xyz="0.0 -8.881784197001253e-18 -0.009200000000000002" rpy="-1.67632942359465e-30 -7.769107711157792e-63 -4.9242570266434686e-33" />
        <parent link="rotor_3" />
        <child link="link_6" />
    </joint>
    <joint name="link_6_Rigid-27" type="fixed">
        <origin xyz="0.0 0.02379999999999999 -0.023799999999999998" rpy="3.447047926773262e-33 -1.5707963267948966 0" />
        <parent link="link_6" />
        <child link="link_7" />
    </joint>
    <joint name="joint_4" type="revolute">
        <origin xyz="0.0 -0.017100000000000008 -0.027000000000000003" rpy="0 0 -3.14" />
        <parent link="link_9" />
        <child link="rotor_4" />
        <axis xyz="0.0 0.0 -1.0" />
        <limit lower="0.0" upper="3.141593" effort="1000000" velocity="1000000" />
    </joint>
    <joint name="link_3_Rigid-32" type="fixed">
        <origin xyz="0.08 -8.881784197001253e-18 0.0" rpy="-6.923910743063235e-30 -0.0 0.0" />
        <parent link="link_3" />
        <child link="link_4" />
    </joint>
    <joint name="link_7_Rigid-34" type="fixed">
        <origin xyz="0.0 0.08 0.0" rpy="1.4791141972893971e-30 1.5707963267948966 0" />
        <parent link="link_7" />
        <child link="link_8" />
    </joint>
    <joint name="link_8_Rigid-35" type="fixed">
        <origin xyz="0.0 0.08 0.0" rpy="3.141592653589793 4.2216708073399146e-32 4.162888818279106e-63" />
        <parent link="link_8" />
        <child link="link_9" />
    </joint>
    <joint name="joint_5" type="revolute">
        <origin xyz="-0.027000000000000027 0.0 0.0171" rpy="1.57 5.048709793414476e-29 3.174730387285158e-31" />
        <parent link="link_10" />
        <child link="rotor_5" />
        <axis xyz="1.0 -0.0 -2.524354896707238e-29" />
        <limit lower="-1.57" upper="1.57" effort="1000000" velocity="1000000" />
    </joint>
    <joint name="rotor_4_Rigid-39" type="fixed">
        <origin xyz="0.0 0.0 -0.0092" rpy="-3.141592653589793 2.524354896707238e-29 1.653910092303433e-29" />
        <parent link="rotor_4" />
        <child link="link_10" />
    </joint>
    <joint name="link_4_Rigid-42" type="fixed">
        <origin xyz="0.08000000000000002 0.0 0.0" rpy="3.141592653589793 1.5777218104420236e-30 -4.0716994493270166e-61" />
        <parent link="link_4" />
        <child link="link_5" />
    </joint>
    <joint name="joint_3" type="revolute">
        <origin xyz="0.021799999999999996 0.0 0.026146679999999995" rpy="-3.141592653589793 2.5670893929194337e-64 -2.6093117100671623e-33" />
        <parent link="link_5" />
        <child link="rotor_3" />
        <axis xyz="0.0 -1.5777218104420236e-30 -0.9999999999999999" />
        <limit lower="1.570796" upper="4.712389" effort="1000000" velocity="1000000" />
    </joint>
    <joint name="rotor_5_Rigid-44" type="fixed">
        <origin xyz="-0.009199999999999982 0.0 0.0" rpy="-3.141592653589793 2.524354896707238e-29 4.930380657631324e-32" />
        <parent link="rotor_5" />
        <child link="link_11" />
    </joint>
    <joint name="joint_6" type="revolute">
        <origin xyz="-0.021799999999999996 -3.552713678800501e-17 -0.02614669" rpy="-3.141592653589793 -2.361394443690113e-59 3.14" />
        <parent link="link_11" />
        <child link="rotor_6" />
        <axis xyz="0.0 -2.524354896707238e-29 1.0" />
        <limit lower="1.570796" upper="4.712389" effort="1000000" velocity="1000000" />
    </joint>
    <joint name="rotor_6_Rigid-47" type="fixed">
        <origin xyz="0.0 0.0 0.0092" rpy="3.141592653589793 3.002640203269837e-58 1.1894683299826317e-29" />
        <parent link="rotor_6" />
        <child link="gripper" />
    </joint>
</robot>